Workbook

Sheet Overview

Sheet Starbucks

Sheet Nepal

Sheet Strategy

Sheet Sources

Sheet _calc
A1: Stores (text) | B1: =TEXT('Starbucks Financial data'!B4,"#,##0") -> 40,990
A2: Revenue (text) | B2: ="US$"&TEXT('Starbucks Financial data'!B5,"0.0")&"bn" -> US$37.2bn
A3: Margin (text) | B3: =TEXT('Starbucks Financial data'!B6,"0.0")&"%" -> 7.9%
A4: Margin sub | B4: ="▼ "&'Starbucks Financial data'!B7&" bps contraction" -> ▼ 710 bps contraction
A5: US+China share (text) | B5: =TEXT(('Starbucks Financial data'!B10+'Starbucks Financial data'!B11)/'Starbucks Financial data'!B4,"0%") -> 61%
A6: Population (text) | B6: =TEXT('2_Nepal_Macroeconomic'!B4/1000000,"0.0")&"m" -> 29.6m
A7: GDP per capita (text) | B7: ="US$"&TEXT('2_Nepal_Macroeconomic'!B5,"#,##0") -> US$1,536
A8: Affordability sub | B8: ="Beverage ≈ "&TEXT(3.5/'2_Nepal_Macroeconomic'!B5,"0.00%")&" of GDP p.c." -> Beverage ≈ 0.23% of GDP p.c.
A9: GDP growth (text) | B9: =TEXT('2_Nepal_Macroeconomic'!B7,"0.0")&"%" -> 4.4%
A10: Growth sub | B10: ="FY2026 projection "&TEXT('2_Nepal_Macroeconomic'!B8,"0.0")&"%" -> FY2026 projection 2.3%
A11: Coffee gap (text) | B11: =TEXT('3_Nepal_Coffee'!B4-'3_Nepal_Coffee'!B5,"#,##0")&" t" -> 1,214 t
A13: Chart data - coffee (tonnes)
A14: Consumption | B14: ='3_Nepal_Coffee'!B4 -> 1800 | C14: 0 | D14: Stack 1 = value / low est.; Stack 2 = upper estimate range
A15: Production | B15: ='3_Nepal_Coffee'!B5 -> 586 | C15: 0
A16: Imports | B16: ='3_Nepal_Coffee'!B6 -> 1200 | C16: ='3_Nepal_Coffee'!B7-'3_Nepal_Coffee'!B6 -> 200
A19: Chart data - Hofstede (Nepal, US)
A20: ='4_Hofstede'!A4 -> Power distance | B20: ='4_Hofstede'!B4 -> 65 | C20: ='4_Hofstede'!C4 -> 40
A21: ='4_Hofstede'!A5 -> Individualism | B21: ='4_Hofstede'!B5 -> 30 | C21: ='4_Hofstede'!C5 -> 91
A22: ='4_Hofstede'!A6 -> Motivation towards achievement | B22: ='4_Hofstede'!B6 -> 40 | C22: ='4_Hofstede'!C6 -> 62
A23: ='4_Hofstede'!A7 -> Uncertainty avoidance | B23: ='4_Hofstede'!B7 -> 40 | C23: ='4_Hofstede'!C7 -> 46
A25: Chart data - stores
A26: US | B26: ='Starbucks Financial data'!B10 -> 16864
A27: China | B27: ='Starbucks Financial data'!B11 -> 8011
A28: Rest of world | B28: ='Starbucks Financial data'!B4-'Starbucks Financial data'!B10-'Starbucks Financial data'!B11 -> 16115
A32: Boyu target (text) | B32: =TEXT('Starbucks Financial data'!B17,"#,##0")&" stores" -> 20,000 stores
A33: Global comp sales | B33: =TEXT('Starbucks Financial data'!B8,"0")&"%" -> -1%
A34: NA comp sales | B34: =TEXT('Starbucks Financial data'!B9,"0")&"%" -> -2%
A35: Partner labour investment | B35: ="US$"&'Starbucks Financial data'!B13&"m" -> US$500m
A36: Bean Stock | B36: =TEXT('Starbucks Financial data'!B14,"#,##0") -> 230,000
A37: Global comparable sales | B37: ='Starbucks Financial data'!B8 -> -1
A38: North America | B38: ='Starbucks Financial data'!B9 -> -2
A39: Boyu Capital | B39: ='Starbucks Financial data'!B15 -> 60
A40: Starbucks | B40: ='Starbucks Financial data'!B16 -> 40
A41: GDP (text) | B41: ="US$"&TEXT('2_Nepal_Macroeconomic'!B6,"0.0")&"bn" -> US$45.5bn
A42: Unemployment (text) | B42: =TEXT('2_Nepal_Macroeconomic'!B13,"0.0")&"%" -> 10.5%
A43: Remittances (text) | B43: =TEXT('2_Nepal_Macroeconomic'!B14,"0")&"% of GDP" -> 26% of GDP
A44: Tourists (text) | B44: =TEXT('2_Nepal_Macroeconomic'!B18/1000000,"0.00")&"m" -> 1.16m
A45: Hydropower (text) | B45: ='2_Nepal_Macroeconomic'!B16&" MW" -> 385 MW
A46: 2025 / FY2025 | B46: ='2_Nepal_Macroeconomic'!B7 -> 4.4 | C46: ='2_Nepal_Macroeconomic'!B10 -> 4.1
A47: FY2026 | B47: ='2_Nepal_Macroeconomic'!B8 -> 2.3 | C47: ='2_Nepal_Macroeconomic'!B11 -> 4.3
...

Sheet Starbucks Financial data
A1: Starbucks Corporation — FY2025 Financial Data | I1: ← Back to Overview
A3: Metric | B3: Value | C3: Unit | D3: Source
A4: Total stores globally | B4: 40990 | C4: stores | D4: Starbucks (2025a)
A5: Net revenue | B5: 37.2 | C5: US$ billion | D5: Starbucks (2025a)
A6: GAAP operating margin | B6: 7.9 | C6: % | D6: Starbucks (2025a)
A7: Margin contraction | B7: 710 | C7: basis points | D7: Starbucks (2025a)
A8: Global comparable store sales | B8: -1 | C8: % change | D8: Starbucks (2025a)
A9: North America comparable store sales | B9: -2 | C9: % change | D9: Starbucks (2025a)
A10: US stores | B10: 16864 | C10: stores | D10: Starbucks (2025a)
A11: China stores | B11: 8011 | C11: stores | D11: Starbucks (2025a)
A12: US + China share of portfolio | B12: 61 | C12: % | D12: Starbucks (2025a)
A13: Partner labour investment | B13: 500 | C13: US$ million | D13: Starbucks (2025c)
A14: Bean Stock recipients | B14: 230000 | C14: partners (2024) | D14: Starbucks (2025b)
A15: Boyu JV — Boyu stake | B15: 60 | C15: % | D15: Starbucks (2026a)
... A17: Boyu JV — China growth target | B17: 20000 | C17: stores | D17: Starbucks (2026a)
A19: Source: Starbucks investor relations and corporate communications, FY2025.

Sheet 2_Nepal_Macroeconomic
A1: Nepal — Macroeconomic Indicators | I1: ← Back to Overview
A3: Indicator | B3: Value | C3: Unit | D3: Period | E3: Source
A4: Population | B4: 29618118 | C4: people | D4: 2025 | E4: World Bank (2025)
A5: GDP per capita | B5: 1535.9 | C5: US$ | D5: 2025 | E5: World Bank (2025)
A6: GDP | B6: 45.49 | C6: US$ billion | D6: 2025 | E6: World Bank (2025)
A7: GDP growth | B7: 4.4 | C7: % | D7: 2025 | E7: World Bank (2025)
A8: GDP growth projection | B8: 2.3 | C8: % | D8: FY2026 | E8: World Bank (2026)
A9: GDP growth projection (avg) | B9: 4.4 | C9: % | D9: FY2027–FY2028 | E9: World Bank (2026)
A10: Inflation | B10: 4.1 | C10: % | D10: FY2025 | E10: World Bank (2026)
A11: Inflation projection | B11: 4.3 | C11: % | D11: FY2026 | E11: World Bank (2026)
A12: Inflation projection | B12: 5.1 | C12: % | D12: FY2027 | E12: World Bank (2026)
A13: Unemployment | B13: 10.5 | C13: % | D13: 2025 | E13: World Bank (2025)
A14: Personal remittances | B14: 26 | C14: % of GDP | D14: 2024 | E14: World Bank (2025)
A15: September 2025 unrest losses | B15: 1.3 | C15: % of GDP | D15: 2025 | E15: World Bank (2026)
A16: Hydropower added | B16: 385 | C16: MW | D16: H1FY2026 | E16: World Bank (2026)
A17: Currency peg | B17: Indian rupee | C17: — | D17: Current | E17: World Bank (2026)
A18: International tourist arrivals | B18: 1158459 | C18: visitors | D18: 2025 | E18: Nepal Tourism Board
A20: Source: World Bank Nepal Development Update (April 2026); World Bank Open Data.

Sheet 3_Nepal_Coffee
A1: Nepal — Coffee Supply, Demand and Constraints | I1: ← Back to Overview
A3: Metric | B3: Value | C3: Unit | D3: Source / Note
A4: Domestic consumption | B4: 1800 | C4: metric tons/year | D4: Lamichhane and Malla (2025)
A5: Domestic production | B5: 586 | C5: metric tons (2024–25) | D5: Lamichhane and Malla (2025)
A6: Imports (low estimate) | B6: 1200 | C6: metric tons/year | D6: Lamichhane and Malla (2025)
A7: Imports (high estimate) | B7: 1400 | C7: metric tons/year | D7: Lamichhane and Malla (2025)
A8: Supply gap (author's calc) | B8: 1214 | C8: metric tons | D8: Author's calculation: 1800 − 586
A9: Chemical fertiliser ban | B9: Yes | C9: — | D9: National Coffee Policy 2003
A10: Café culture boom | B10: Yes | C10: — | D10: Lamichhane and Malla (2025)
A11: Third-wave coffee movement | B11: Yes | C11: — | D11: Lamichhane and Malla (2025)
A13: Source: Lamichhane, R. and Malla, B. (2025) 'Brewing change in Nepali coffee', The Kathmandu Post.

Sheet 4_Hofstede
A1: Hofstede Cultural Dimensions — Nepal vs United States | I1: ← Back to Overview
A3: Dimension | B3: Nepal | C3: United States | D3: Gap (Nepal − US) | E3: Available | F3: Source
A4: Power distance | B4: 65 | C4: 40 | D4: 25 | E4: Yes | F4: Culture Factor Group (2026)
A5: Individualism | B5: 30 | C5: 91 | D5: -61 | E5: Yes | F5: Culture Factor Group (2026)
A6: Motivation towards achievement | B6: 40 | C6: 62 | D6: -22 | E6: Yes | F6: Culture Factor Group (2026)
A7: Uncertainty avoidance | B7: 40 | C7: 46 | D7: -6 | E7: Yes | F7: Culture Factor Group (2026)
A8: Long-term orientation | B8: n/a | C8: 50 | D8: — | E8: No published score for Nepal | F8: Culture Factor Group (2026)
A9: Indulgence | B9: n/a | C9: 68 | D9: — | E9: No published score for Nepal | F9: Culture Factor Group (2026)
A11: Source: Culture Factor Group (2026) Country comparison tool. Nepal has no published score for LTO or Indulgence.

Sheet 5_RBV_VRIN
A1: Resource-Based View (VRIN) — Transferability to Nepal | I1: ← Back to Overview
A3: Resource | B3: Valuable | C3: Rare | D3: Costly to Imitate | E3: Non-substitutable | F3: Transfers to Nepal? | G3: Rationale | H3: Source
A4: Brand and 'third place' | B4: ✓ | C4: ✓ | D4: ✓ | E4: ✓ | F4: YES | G4: Socially complex, causally ambiguous; no premium incumbent | H4: Barney (1991)
A5: Partner capability | B5: ✓ | C5: ✓ | D5: ✓ | E5: ✓ | F5: YES | G5: Training and culture are non-purchasable | H5: Starbucks (2025b; 2025c)
A6: Roasting craft | B6: ✓ | C6: ✓ | D6: ✓ | E6: ✓ | F6: YES | G6: Codified knowledge; travels with the firm | H6: Barney (1991)
A7: Digital ecosystem | B7: ✓ | C7: ✓ | D7: ✓ | E7: ✓ | F7: PARTIAL | G7: Depends on smartphone and card penetration | H7: Author's assessment
A8: Scale supply chain | B8: ✓ | C8: ✗ | D8: ✗ | E8: ✓ | F8: NO | G8: Value depends on store density Nepal cannot supply | H8: Barney (1991)
A9: Real-estate capability | B9: ✓ | C9: ✗ | D9: ✗ | E9: ✓ | F9: NO | G9: Advantage is a function of mature-market scale | H9: Barney (1991)
A11: VRIN marks are the author's analytical judgement based on Barney (1991) and Starbucks corporate data.

Sheet 6_OLI
A1: Dunning's OLI Paradigm — Applied to Starbucks in Nepal | I1: ← Back to Overview
A3: OLI Component | B3: Starbucks' Position | C3: Evidence | D3: Source
A4: Ownership (O) | B4: Brand equity, roasting technology, store operating systems, digital platform | C4: 40,990 stores; US$37.2bn revenue FY2025 | D4: Starbucks (2025a)
A5: Location (L) | B5: 29.6m consumers, high-altitude Arabica, 385 MW hydropower added H1FY2026 | C5: Population 29,618,118; 385 MW added | D5: World Bank (2025; 2026)
A6: Internalisation (I) | B6: Greater control over brand standards, IP and operating processes | C6: US$500m invested in partner labour hours; 40% stake in China JV | D6: Starbucks (2025c; 2026a)
A8: OLI justifies equity entry without dictating its form. Internalisation is a matter of degree, not necessity.

Sheet 7_Entry_Mode
A1: Entry-Mode Assessment — Control vs Exposure | I1: ← Back to Overview
A3: Entry Mode | B3: Control | C3: Capability Transfer | D3: Local Knowledge | E3: Risk Sharing | F3: Capital Exposure | G3: Verdict | H3: Source
A4: Wholly owned | B4: High | C4: High | D4: Low | E4: Low | F4: High | G4: Rejected: concentrates institutional risk | H4: Author's assessment
A5: Joint venture | B5: Shared | C5: High | D5: High | E5: High | F5: Medium | G5: RECOMMENDED: balances control, capability and risk | H5: Fischer and Roy (2017); Starbucks (2026a)
A6: Franchise | B6: Low | C6: Medium | D6: High | E6: Medium | F6: Low | G6: Fallback: fastest footprint, weak control | H6: Author's assessment
A7: Exporting | B7: — | C7: Low | D7: Low | E7: Low | F7: Low | G7: Rejected: cannot deliver 'third place' | H7: Author's assessment
A9: Joint venture mirrors Starbucks' India JV (Fischer and Roy, 2017) and 2026 China restructuring (Starbucks, 2026a).

Sheet 8_FITTA_FDI
A1: Nepal — Foreign Investment Regulatory Framework | I1: ← Back to Overview
A3: Item | B3: Detail | C3: Status | D3: Source
A4: Governing legislation | B4: FITTA 2019; Industrial Enterprises Act 2020 | C4: Current | D4: Department of Industries (2026)
A5: Retail restriction | B5: Retail business restricted, BUT excludes international chain retail trading in ≥2 countries | C5: Current | D5: Department of Industries (2026)
A6: Local catering | B6: Closed to foreign equity | C6: Current | D6: Department of Industries (2026)
A7: Automatic route expansion | B7: 102 industry areas; NPR 500m ceiling removed | C7: Feb 2026 (Gazette 2082/11/04) | D7: Nepal Gazette (2026)
A8: Required documents | B8: Project report, JVA (if >1 investor), home-bank Financial Credibility Certificate | C8: Current | D8: Department of Industries (2026)
A9: Currency | B9: Pegged to Indian rupee | C9: Current | D9: World Bank (2026)
A11: Feb 2026 change verified via legal commentary (Niti Partners / Mondaq); primary Gazette text not directly accessed.

Sheet 9_SDG_Data
A1: UN Sustainable Development Goals — Starbucks Data | I1: ← Back to Overview
A3: SDG | B3: Target | C3: Starbucks Metric | D3: Value | E3: Source
A4: SDG 8 | B4: 8.5, 8.6 | C4: Bean Stock recipients | D4: 230,000+ partners (2024) | E4: Starbucks (2025b)
A5: SDG 8 | B5: 8.5, 8.6 | C5: Green Apron training | D5: US$500m invested in partner labour hours | E5: Starbucks (2025c)
A6: SDG 12 | B6: 12.3, 12.5 | C6: Reusable cup increase | D6: +77% when customers sit and stay | E6: Starbucks (2025b)
A7: SDG 12 | B7: 12.3, 12.5 | C7: Stores verified for energy/water/waste | D7: 13,000+ coffeehouses | E7: Starbucks (2025b)
A8: SDG 13 | B8: 13.2, 13.3 | C8: Total emissions vs FY2019 baseline | D8: +7% (Scope 1, 2 and 3) | E8: Starbucks (2025b)
A9: SDG 13 | B9: 13.2, 13.3 | C9: Scope 1+2 market-based emissions | D9: −17% vs FY2019 | E9: Starbucks (2025b)
A10: SDG 13 | B10: 13.2, 13.3 | C10: 2030 target | D10: 50% absolute reduction from FY2019 (under reassessment) | E10: Starbucks (2025b)
A12: Starbucks retains a stated 2030 goal of 50% absolute reduction; currently reassessing.

Sheet 10_Citation_Audit
A1: Citation and Reference Audit — Full Mapping | I1: ← Back to Overview
A3: In-text Citation | B3: Reference List Entry | C3: Source Type | D3: Verified | E3: Notes
A4: Barney (1991) | B4: Barney, J. (1991) 'Firm resources and sustained competitive advantage', Journal of Management, 17(1), pp. 99–120. | C4: Peer-reviewed | D4: Yes | E4: Primary RBV source
A5: Culture Factor Group (2026) | B5: Culture Factor Group (2026) Country comparison tool: Nepal and United States. | C5: Secondary database | D5: Yes | E5: Hofstede scores verified live
A6: Department of Industries (2026) | B6: Department of Industries (2026) Foreign investment. Government of Nepal. | C6: Government | D6: Yes | E6: Primary regulatory source
A7: DiMaggio and Powell (1983) | B7: DiMaggio, P.J. and Powell, W.W. (1983) 'The iron cage revisited', ASR, 48(2), pp. 147–160. | C7: Peer-reviewed | D7: Yes | E7: Primary institutional theory source
A8: Dunning (1988) | B8: Dunning, J.H. (1988) 'The eclectic paradigm of international production', JIBS, 19(1), pp. 1–31. | C8: Peer-reviewed | D8: Yes | E8: Primary OLI source
A9: Fischer and Roy (2017) | B9: Fischer, D. and Roy, K. (2017) 'Market entry in India: the curious case of Starbucks', Rutgers Business Review, 4(2), pp. 37–49. | C9: Peer-reviewed | D9: Yes | E9: India JV case study
A10: Hofstede (2001) | B10: Hofstede, G. (2001) Culture's consequences, 2nd edn. Sage. | C10: Academic text | D10: Yes | E10: Framework source
A11: Lamichhane and Malla (2025) | B11: Lamichhane, R. and Malla, B. (2025) 'Brewing change in Nepali coffee', The Kathmandu Post, 14 February. | C11: Newspaper | D11: Yes | E11: Coffee data; secondary source
A12: Nepal Gazette (2026) | B12: Nepal Gazette (2026) Notification expanding automatic FDI route, 16 February (2082/11/04). | C12: Government | D12: Secondary | E12: Verified via legal commentary; primary text not directly accessed
A13: Starbucks (2025a) | B13: Starbucks (2025a) Q4 and full fiscal year 2025 results, 29 October. | C13: Corporate | D13: Yes | E13: Primary financial data
A14: Starbucks (2025b) | B14: Starbucks (2025b) Fiscal 2025 global impact report. | C14: Corporate | D14: Yes | E14: Primary sustainability data
... A18: World Bank (2026) | B18: World Bank (2026) Nepal development update, April 2026. | C18: Multilateral | D18: Yes | E18: Primary macro/political data
A20: All 15 in-text citations mapped to reference list entries. No orphan references. No ACT 2 Starbucks Case.md. No Israel claim. Australia A$105m removed.

Sheet 11_Derived_Calcs
A1: Derived Calculations — Transparent Methodology | I1: ← Back to Overview
A3: Calculation | B3: Formula | C3: Inputs | D3: Result | E3: Label
A4: Coffee supply gap | B4: Consumption − Production | C4: 1,800 t − 586 t | D4: 1,214 t | E4: Author's calculation
A5: Beverage affordability | B5: Price / GDP per capita × 100 | C5: US$3.50 / US$1,535.9 × 100 | D5: 0.23% | E5: Author's calculation; indicative only
A6: US + China portfolio share | B6: (US stores + China stores) / Total stores × 100 | C6: (16,864 + 8,011) / 40,990 × 100 | D6: 61% | E6: Author's calculation from Starbucks (2025a)
A7: Import dependence | B7: Imports / Consumption × 100 | C7: 1,200–1,400 / 1,800 × 100 | D7: 67–78% | E7: Author's calculation from Lamichhane and Malla (2025)
A9: All derived figures are labelled as author's calculations in the report and figures.

Sheet 12_Verification_Exceptions
A1: Verification Exceptions — Disclosed Uncertainties | I1: ← Back to Overview
A3: Claim | B3: Status | C3: Treatment in Report | D3: Notes
A4: Coffee supply gap 1,214 t | B4: Author's calculation | C4: Labelled as calculation in figure and Appendix C | D4: Derived from cited figures
A5: US$3.50 = 0.23% GDP per capita | B5: Author's calculation | C5: Indicative affordability comparison only | D5: GDP per capita ≠ disposable income
A6: Feb 2026 FDI expansion | B6: Secondary source | C6: Disclosed in Appendix C | D6: Gazette notification via legal commentary; primary text not accessed
A7: Hofstede LTO & Indulgence (Nepal) | B7: Unavailable | C7: Excluded rather than estimated | D7: No published score
A8: Starbucks Australia A$105m | B8: Removed | C8: Disclosed in Appendix C | D8: Currency not independently verified
A9: ACT 2 Starbucks Case.md | B9: Removed | C9: Not cited anywhere | D9: Internal file, not academic source
A10: Israel claim | B10: Removed | C10: Not present | D10: No credible source found
A12: No derived figure is presented as though a source reported it. No invented URLs or references.
